from celery import shared_task
from celery.utils.log import get_task_logger

from .models import Email
from .services import email_failed
from .services import email_send as email_send_service

logger = get_task_logger(__name__)


def _email_send_failure(self, exc, task_id, args, kwargs, einfo):
    email_id = args[0]
    email = Email.objects.get(id=email_id)

    email_failed(email)


@shared_task(bind=True, on_failure=_email_send_failure)
def email_send(self, email_id):
    email = Email.objects.get(id=email_id)

    try:
        email_send_service(email)
    except Exception as exc:
        # https://docs.celeryq.dev/en/stable/userguide/tasks.html#retrying
        logger.warning(f"Exception occurred while sending email: {exc}")
        self.retry(exc=exc, countdown=5)
